{
  "uid" : "9a0d9f95e0b8c437",
  "name" : "table merge in sync",
  "fullName" : "test_pipeline.TestPipeline#test_merge_sync",
  "historyId" : "edfd051c418b47aafa88b402eedbe088",
  "time" : {
    "start" : 1660126811142,
    "stop" : 1660126811560,
    "duration" : 418
  },
  "status" : "broken",
  "statusMessage" : "IndexError: tuple index out of range",
  "statusTrace" : "self = <lib.cli.Job object at 0x7faabe314c90>\n\n    def start(self):\n        try:\n>           status = self.status()\n\n../lib/cli.py:2504: \n_ _ _ _ _ _ _ _ _ _ _ _ _ _ _ _ _ _ _ _ _ _ _ _ _ _ _ _ _ _ _ _ _ _ _ _ _ _ _ _ \n\nself = <lib.cli.Job object at 0x7faabe314c90>, res = None, quiet = True\n\n    def status(self, res=None, quiet=True):\n        if res is None:\n>           res = req.get(\"/Task/\" + self.id).json()\nE           TypeError: can only concatenate str (not \"NoneType\") to str\n\n../lib/cli.py:2531: TypeError\n\nDuring handling of the above exception, another exception occurred:\n\nself = <test.test_pipeline.TestPipeline object at 0x7faabe358f90>\n\n    @allure.title(\"table merge in sync\")\n    def test_merge_sync(self):\n        p = make_new_pipeline(f\"merge_sync_{random_str()}\")\n        p1 = p.readFrom(source_mongo_1)\n        p2 = p.readFrom(source_mongo_2)\n        p1.dag.jobType = JobType.sync\n        p3 = p1.merge(p2, [('id', 'id')]).writeTo(sink_mysql)\n>       p3.start()\n\ntest_pipeline.py:173: \n_ _ _ _ _ _ _ _ _ _ _ _ _ _ _ _ _ _ _ _ _ _ _ _ _ _ _ _ _ _ _ _ _ _ _ _ _ _ _ _ \n../lib/cli.py:112: in func_wrapper\n    return obj(*args, **kargs)\n../lib/cli.py:1936: in start\n    if job.start():\n../lib/cli.py:2508: in start\n    logger.info(\"job {} save failed.\")\n_ _ _ _ _ _ _ _ _ _ _ _ _ _ _ _ _ _ _ _ _ _ _ _ _ _ _ _ _ _ _ _ _ _ _ _ _ _ _ _ \n\nself = <lib.log.Logger object at 0x7faabf3f49d0>\nargs = ('job {} save failed.',), kargs = {}\nmsg = 'job \\x1b[1;32m{}\\x1b[0m save failed.'\n\n    def info(self, *args, **kargs):\n        msg = args[0].replace(\"{}\", \"\\033[1;32m{}\\033[0m\")\n>       self._print(msg.format(*args[1:]), **kargs)\nE       IndexError: tuple index out of range\n\n../lib/log.py:64: IndexError",
  "flaky" : false,
  "newFailed" : false,
  "beforeStages" : [ ],
  "afterStages" : [ ],
  "labels" : [ {
    "name" : "feature",
    "value" : "pipeline"
  }, {
    "name" : "suite",
    "value" : "test_pipeline"
  }, {
    "name" : "subSuite",
    "value" : "TestPipeline"
  }, {
    "name" : "host",
    "value" : "cf4adbe1056c"
  }, {
    "name" : "thread",
    "value" : "831-MainThread"
  }, {
    "name" : "framework",
    "value" : "pytest"
  }, {
    "name" : "language",
    "value" : "cpython3"
  }, {
    "name" : "package",
    "value" : "test_pipeline"
  }, {
    "name" : "resultFormat",
    "value" : "allure2"
  } ],
  "parameters" : [ ],
  "links" : [ ],
  "hidden" : false,
  "retry" : false,
  "extra" : {
    "severity" : "normal",
    "retries" : [ ],
    "categories" : [ {
      "name" : "Test defects",
      "matchedStatuses" : [ ],
      "flaky" : false
    } ],
    "tags" : [ ]
  },
  "source" : "9a0d9f95e0b8c437.json",
  "parameterValues" : [ ]
}